Workbook

Sheet Projects
A1: Projects | N1: =IF(A5="","",A5) -> Sample Project
A2: One row per project; its invoices list underneath (auto from the Project tag on Invoices). To add a project, fill in the next empty row (name + total value) — it appears in the Invoices dropdown and totals automatically. Blue = editable, black = formula. | N2: =IF(A12="","",A12)
N3: =IF(A19="","",A19)
A4: Project | B4: Client | C4: Status | D4: Total value | E4: Original value | F4: Billed | G4: Unbilled | N4: =IF(A26="","",A26)
A5: Sample Project | B5: Acme Corp | C5: Active | D5: 10000 | E5: $12,000 | F5: =IF($A$5="","",SUMIF(Invoices!$J$5:$J$44,$A$5,Invoices!$C$5:$C$44)) -> 1000 | G5: =IF($A$5="","",D5-F5) -> 9000 | I5: =IF(Invoices!J5="","",Invoices!J5&"#"&COUNTIFS(Invoices!$J$5:$J5,Invoices!J5)) -> Sample Project#1 | J5: =Invoices!A5 -> 012026 | K5: =Invoices!E5 -> 46037 | L5: =Invoices!C5 -> 1000 | N5: =IF(A33="","",A33)
A6: =IFERROR(INDEX($J$5:$J$44,MATCH($A$5&"#"&1,$I$5:$I$44,0)),"") -> 012026 | B6: =IFERROR(INDEX($K$5:$K$44,MATCH($A$5&"#"&1,$I$5:$I$44,0)),"") -> 46037 | F6: =IFERROR(INDEX($L$5:$L$44,MATCH($A$5&"#"&1,$I$5:$I$44,0)),"") -> 1000 | I6: =IF(Invoices!J6="","",Invoices!J6&"#"&COUNTIFS(Invoices!$J$5:$J6,Invoices!J6)) | J6: =Invoices!A6 -> 0 | K6: =Invoices!E6 -> 0 | L6: =Invoices!C6 -> 0 | N6: =IF(A40="","",A40)
A7: =IFERROR(INDEX($J$5:$J$44,MATCH($A$5&"#"&2,$I$5:$I$44,0)),"") | B7: =IFERROR(INDEX($K$5:$K$44,MATCH($A$5&"#"&2,$I$5:$I$44,0)),"") | F7: =IFERROR(INDEX($L$5:$L$44,MATCH($A$5&"#"&2,$I$5:$I$44,0)),"") | I7: =IF(Invoices!J7="","",Invoices!J7&"#"&COUNTIFS(Invoices!$J$5:$J7,Invoices!J7)) | J7: =Invoices!A7 -> 0 | K7: =Invoices!E7 -> 0 | L7: =Invoices!C7 -> 0 | N7: =IF(A47="","",A47)
A8: =IFERROR(INDEX($J$5:$J$44,MATCH($A$5&"#"&3,$I$5:$I$44,0)),"") | B8: =IFERROR(INDEX($K$5:$K$44,MATCH($A$5&"#"&3,$I$5:$I$44,0)),"") | F8: =IFERROR(INDEX($L$5:$L$44,MATCH($A$5&"#"&3,$I$5:$I$44,0)),"") | I8: =IF(Invoices!J8="","",Invoices!J8&"#"&COUNTIFS(Invoices!$J$5:$J8,Invoices!J8)) | J8: =Invoices!A8 -> 0 | K8: =Invoices!E8 -> 0 | L8: =Invoices!C8 -> 0 | N8: =IF(A54="","",A54)
A9: =IFERROR(INDEX($J$5:$J$44,MATCH($A$5&"#"&4,$I$5:$I$44,0)),"") | B9: =IFERROR(INDEX($K$5:$K$44,MATCH($A$5&"#"&4,$I$5:$I$44,0)),"") | F9: =IFERROR(INDEX($L$5:$L$44,MATCH($A$5&"#"&4,$I$5:$I$44,0)),"") | I9: =IF(Invoices!J9="","",Invoices!J9&"#"&COUNTIFS(Invoices!$J$5:$J9,Invoices!J9)) | J9: =Invoices!A9 -> 0 | K9: =Invoices!E9 -> 0 | L9: =Invoices!C9 -> 0 | N9: =IF(A61="","",A61)
A10: =IFERROR(INDEX($J$5:$J$44,MATCH($A$5&"#"&5,$I$5:$I$44,0)),"") | B10: =IFERROR(INDEX($K$5:$K$44,MATCH($A$5&"#"&5,$I$5:$I$44,0)),"") | F10: =IFERROR(INDEX($L$5:$L$44,MATCH($A$5&"#"&5,$I$5:$I$44,0)),"") | I10: =IF(Invoices!J10="","",Invoices!J10&"#"&COUNTIFS(Invoices!$J$5:$J10,Invoices!J10)) | J10: =Invoices!A10 -> 0 | K10: =Invoices!E10 -> 0 | L10: =Invoices!C10 -> 0 | N10: =IF(A68="","",A68)
A11: =IFERROR(INDEX($J$5:$J$44,MATCH($A$5&"#"&6,$I$5:$I$44,0)),"") | B11: =IFERROR(INDEX($K$5:$K$44,MATCH($A$5&"#"&6,$I$5:$I$44,0)),"") | F11: =IFERROR(INDEX($L$5:$L$44,MATCH($A$5&"#"&6,$I$5:$I$44,0)),"") | I11: =IF(Invoices!J11="","",Invoices!J11&"#"&COUNTIFS(Invoices!$J$5:$J11,Invoices!J11)) | J11: =Invoices!A11 -> 0 | K11: =Invoices!E11 -> 0 | L11: =Invoices!C11 -> 0
F12: =IF($A$12="","",SUMIF(Invoices!$J$5:$J$44,$A$12,Invoices!$C$5:$C$44)) | G12: =IF($A$12="","",D12-F12) | I12: =IF(Invoices!J12="","",Invoices!J12&"#"&COUNTIFS(Invoices!$J$5:$J12,Invoices!J12)) | J12: =Invoices!A12 -> 0 | K12: =Invoices!E12 -> 0 | L12: =Invoices!C12 -> 0
A13: =IFERROR(INDEX($J$5:$J$44,MATCH($A$12&"#"&1,$I$5:$I$44,0)),"") | B13: =IFERROR(INDEX($K$5:$K$44,MATCH($A$12&"#"&1,$I$5:$I$44,0)),"") | F13: =IFERROR(INDEX($L$5:$L$44,MATCH($A$12&"#"&1,$I$5:$I$44,0)),"") | I13: =IF(Invoices!J13="","",Invoices!J13&"#"&COUNTIFS(Invoices!$J$5:$J13,Invoices!J13)) | J13: =Invoices!A13 -> 0 | K13: =Invoices!E13 -> 0 | L13: =Invoices!C13 -> 0
A14: =IFERROR(INDEX($J$5:$J$44,MATCH($A$12&"#"&2,$I$5:$I$44,0)),"") | B14: =IFERROR(INDEX($K$5:$K$44,MATCH($A$12&"#"&2,$I$5:$I$44,0)),"") | F14: =IFERROR(INDEX($L$5:$L$44,MATCH($A$12&"#"&2,$I$5:$I$44,0)),"") | I14: =IF(Invoices!J14="","",Invoices!J14&"#"&COUNTIFS(Invoices!$J$5:$J14,Invoices!J14)) | J14: =Invoices!A14 -> 0 | K14: =Invoices!E14 -> 0 | L14: =Invoices!C14 -> 0
A15: =IFERROR(INDEX($J$5:$J$44,MATCH($A$12&"#"&3,$I$5:$I$44,0)),"") | B15: =IFERROR(INDEX($K$5:$K$44,MATCH($A$12&"#"&3,$I$5:$I$44,0)),"") | F15: =IFERROR(INDEX($L$5:$L$44,MATCH($A$12&"#"&3,$I$5:$I$44,0)),"") | I15: =IF(Invoices!J15="","",Invoices!J15&"#"&COUNTIFS(Invoices!$J$5:$J15,Invoices!J15)) | J15: =Invoices!A15 -> 0 | K15: =Invoices!E15 -> 0 | L15: =Invoices!C15 -> 0
A16: =IFERROR(INDEX($J$5:$J$44,MATCH($A$12&"#"&4,$I$5:$I$44,0)),"") | B16: =IFERROR(INDEX($K$5:$K$44,MATCH($A$12&"#"&4,$I$5:$I$44,0)),"") | F16: =IFERROR(INDEX($L$5:$L$44,MATCH($A$12&"#"&4,$I$5:$I$44,0)),"") | I16: =IF(Invoices!J16="","",Invoices!J16&"#"&COUNTIFS(Invoices!$J$5:$J16,Invoices!J16)) | J16: =Invoices!A16 -> 0 | K16: =Invoices!E16 -> 0 | L16: =Invoices!C16 -> 0
A17: =IFERROR(INDEX($J$5:$J$44,MATCH($A$12&"#"&5,$I$5:$I$44,0)),"") | B17: =IFERROR(INDEX($K$5:$K$44,MATCH($A$12&"#"&5,$I$5:$I$44,0)),"") | F17: =IFERROR(INDEX($L$5:$L$44,MATCH($A$12&"#"&5,$I$5:$I$44,0)),"") | I17: =IF(Invoices!J17="","",Invoices!J17&"#"&COUNTIFS(Invoices!$J$5:$J17,Invoices!J17)) | J17: =Invoices!A17 -> 0 | K17: =Invoices!E17 -> 0 | L17: =Invoices!C17 -> 0
A18: =IFERROR(INDEX($J$5:$J$44,MATCH($A$12&"#"&6,$I$5:$I$44,0)),"") | B18: =IFERROR(INDEX($K$5:$K$44,MATCH($A$12&"#"&6,$I$5:$I$44,0)),"") | F18: =IFERROR(INDEX($L$5:$L$44,MATCH($A$12&"#"&6,$I$5:$I$44,0)),"") | I18: =IF(Invoices!J18="","",Invoices!J18&"#"&COUNTIFS(Invoices!$J$5:$J18,Invoices!J18)) | J18: =Invoices!A18 -> 0 | K18: =Invoices!E18 -> 0 | L18: =Invoices!C18 -> 0
F19: =IF($A$19="","",SUMIF(Invoices!$J$5:$J$44,$A$19,Invoices!$C$5:$C$44)) | G19: =IF($A$19="","",D19-F19) | I19: =IF(Invoices!J19="","",Invoices!J19&"#"&COUNTIFS(Invoices!$J$5:$J19,Invoices!J19)) | J19: =Invoices!A19 -> 0 | K19: =Invoices!E19 -> 0 | L19: =Invoices!C19 -> 0
A20: =IFERROR(INDEX($J$5:$J$44,MATCH($A$19&"#"&1,$I$5:$I$44,0)),"") | B20: =IFERROR(INDEX($K$5:$K$44,MATCH($A$19&"#"&1,$I$5:$I$44,0)),"") | F20: =IFERROR(INDEX($L$5:$L$44,MATCH($A$19&"#"&1,$I$5:$I$44,0)),"") | I20: =IF(Invoices!J20="","",Invoices!J20&"#"&COUNTIFS(Invoices!$J$5:$J20,Invoices!J20)) | J20: =Invoices!A20 -> 0 | K20: =Invoices!E20 -> 0 | L20: =Invoices!C20 -> 0
A21: =IFERROR(INDEX($J$5:$J$44,MATCH($A$19&"#"&2,$I$5:$I$44,0)),"") | B21: =IFERROR(INDEX($K$5:$K$44,MATCH($A$19&"#"&2,$I$5:$I$44,0)),"") | F21: =IFERROR(INDEX($L$5:$L$44,MATCH($A$19&"#"&2,$I$5:$I$44,0)),"") | I21: =IF(Invoices!J21="","",Invoices!J21&"#"&COUNTIFS(Invoices!$J$5:$J21,Invoices!J21)) | J21: =Invoices!A21 -> 0 | K21: =Invoices!E21 -> 0 | L21: =Invoices!C21 -> 0
A22: =IFERROR(INDEX($J$5:$J$44,MATCH($A$19&"#"&3,$I$5:$I$44,0)),"") | B22: =IFERROR(INDEX($K$5:$K$44,MATCH($A$19&"#"&3,$I$5:$I$44,0)),"") | F22: =IFERROR(INDEX($L$5:$L$44,MATCH($A$19&"#"&3,$I$5:$I$44,0)),"") | I22: =IF(Invoices!J22="","",Invoices!J22&"#"&COUNTIFS(Invoices!$J$5:$J22,Invoices!J22)) | J22: =Invoices!A22 -> 0 | K22: =Invoices!E22 -> 0 | L22: =Invoices!C22 -> 0
A23: =IFERROR(INDEX($J$5:$J$44,MATCH($A$19&"#"&4,$I$5:$I$44,0)),"") | B23: =IFERROR(INDEX($K$5:$K$44,MATCH($A$19&"#"&4,$I$5:$I$44,0)),"") | F23: =IFERROR(INDEX($L$5:$L$44,MATCH($A$19&"#"&4,$I$5:$I$44,0)),"") | I23: =IF(Invoices!J23="","",Invoices!J23&"#"&COUNTIFS(Invoices!$J$5:$J23,Invoices!J23)) | J23: =Invoices!A23 -> 0 | K23: =Invoices!E23 -> 0 | L23: =Invoices!C23 -> 0
A24: =IFERROR(INDEX($J$5:$J$44,MATCH($A$19&"#"&5,$I$5:$I$44,0)),"") | B24: =IFERROR(INDEX($K$5:$K$44,MATCH($A$19&"#"&5,$I$5:$I$44,0)),"") | F24: =IFERROR(INDEX($L$5:$L$44,MATCH($A$19&"#"&5,$I$5:$I$44,0)),"") | I24: =IF(Invoices!J24="","",Invoices!J24&"#"&COUNTIFS(Invoices!$J$5:$J24,Invoices!J24)) | J24: =Invoices!A24 -> 0 | K24: =Invoices!E24 -> 0 | L24: =Invoices!C24 -> 0
A25: =IFERROR(INDEX($J$5:$J$44,MATCH($A$19&"#"&6,$I$5:$I$44,0)),"") | B25: =IFERROR(INDEX($K$5:$K$44,MATCH($A$19&"#"&6,$I$5:$I$44,0)),"") | F25: =IFERROR(INDEX($L$5:$L$44,MATCH($A$19&"#"&6,$I$5:$I$44,0)),"") | I25: =IF(Invoices!J25="","",Invoices!J25&"#"&COUNTIFS(Invoices!$J$5:$J25,Invoices!J25)) | J25: =Invoices!A25 -> 0 | K25: =Invoices!E25 -> 0 | L25: =Invoices!C25 -> 0
F26: =IF($A$26="","",SUMIF(Invoices!$J$5:$J$44,$A$26,Invoices!$C$5:$C$44)) | G26: =IF($A$26="","",D26-F26) | I26: =IF(Invoices!J26="","",Invoices!J26&"#"&COUNTIFS(Invoices!$J$5:$J26,Invoices!J26)) | J26: =Invoices!A26 -> 0 | K26: =Invoices!E26 -> 0 | L26: =Invoices!C26 -> 0
A27: =IFERROR(INDEX($J$5:$J$44,MATCH($A$26&"#"&1,$I$5:$I$44,0)),"") | B27: =IFERROR(INDEX($K$5:$K$44,MATCH($A$26&"#"&1,$I$5:$I$44,0)),"") | F27: =IFERROR(INDEX($L$5:$L$44,MATCH($A$26&"#"&1,$I$5:$I$44,0)),"") | I27: =IF(Invoices!J27="","",Invoices!J27&"#"&COUNTIFS(Invoices!$J$5:$J27,Invoices!J27)) | J27: =Invoices!A27 -> 0 | K27: =Invoices!E27 -> 0 | L27: =Invoices!C27 -> 0
A28: =IFERROR(INDEX($J$5:$J$44,MATCH($A$26&"#"&2,$I$5:$I$44,0)),"") | B28: =IFERROR(INDEX($K$5:$K$44,MATCH($A$26&"#"&2,$I$5:$I$44,0)),"") | F28: =IFERROR(INDEX($L$5:$L$44,MATCH($A$26&"#"&2,$I$5:$I$44,0)),"") | I28: =IF(Invoices!J28="","",Invoices!J28&"#"&COUNTIFS(Invoices!$J$5:$J28,Invoices!J28)) | J28: =Invoices!A28 -> 0 | K28: =Invoices!E28 -> 0 | L28: =Invoices!C28 -> 0
A29: =IFERROR(INDEX($J$5:$J$44,MATCH($A$26&"#"&3,$I$5:$I$44,0)),"") | B29: =IFERROR(INDEX($K$5:$K$44,MATCH($A$26&"#"&3,$I$5:$I$44,0)),"") | F29: =IFERROR(INDEX($L$5:$L$44,MATCH($A$26&"#"&3,$I$5:$I$44,0)),"") | I29: =IF(Invoices!J29="","",Invoices!J29&"#"&COUNTIFS(Invoices!$J$5:$J29,Invoices!J29)) | J29: =Invoices!A29 -> 0 | K29: =Invoices!E29 -> 0 | L29: =Invoices!C29 -> 0
A30: =IFERROR(INDEX($J$5:$J$44,MATCH($A$26&"#"&4,$I$5:$I$44,0)),"") | B30: =IFERROR(INDEX($K$5:$K$44,MATCH($A$26&"#"&4,$I$5:$I$44,0)),"") | F30: =IFERROR(INDEX($L$5:$L$44,MATCH($A$26&"#"&4,$I$5:$I$44,0)),"") | I30: =IF(Invoices!J30="","",Invoices!J30&"#"&COUNTIFS(Invoices!$J$5:$J30,Invoices!J30)) | J30: =Invoices!A30 -> 0 | K30: =Invoices!E30 -> 0 | L30: =Invoices!C30 -> 0
A31: =IFERROR(INDEX($J$5:$J$44,MATCH($A$26&"#"&5,$I$5:$I$44,0)),"") | B31: =IFERROR(INDEX($K$5:$K$44,MATCH($A$26&"#"&5,$I$5:$I$44,0)),"") | F31: =IFERROR(INDEX($L$5:$L$44,MATCH($A$26&"#"&5,$I$5:$I$44,0)),"") | I31: =IF(Invoices!J31="","",Invoices!J31&"#"&COUNTIFS(Invoices!$J$5:$J31,Invoices!J31)) | J31: =Invoices!A31 -> 0 | K31: =Invoices!E31 -> 0 | L31: =Invoices!C31 -> 0
A32: =IFERROR(INDEX($J$5:$J$44,MATCH($A$26&"#"&6,$I$5:$I$44,0)),"") | B32: =IFERROR(INDEX($K$5:$K$44,MATCH($A$26&"#"&6,$I$5:$I$44,0)),"") | F32: =IFERROR(INDEX($L$5:$L$44,MATCH($A$26&"#"&6,$I$5:$I$44,0)),"") | I32: =IF(Invoices!J32="","",Invoices!J32&"#"&COUNTIFS(Invoices!$J$5:$J32,Invoices!J32)) | J32: =Invoices!A32 -> 0 | K32: =Invoices!E32 -> 0 | L32: =Invoices!C32 -> 0
F33: =IF($A$33="","",SUMIF(Invoices!$J$5:$J$44,$A$33,Invoices!$C$5:$C$44)) | G33: =IF($A$33="","",D33-F33) | I33: =IF(Invoices!J33="","",Invoices!J33&"#"&COUNTIFS(Invoices!$J$5:$J33,Invoices!J33)) | J33: =Invoices!A33 -> 0 | K33: =Invoices!E33 -> 0 | L33: =Invoices!C33 -> 0
A34: =IFERROR(INDEX($J$5:$J$44,MATCH($A$33&"#"&1,$I$5:$I$44,0)),"") | B34: =IFERROR(INDEX($K$5:$K$44,MATCH($A$33&"#"&1,$I$5:$I$44,0)),"") | F34: =IFERROR(INDEX($L$5:$L$44,MATCH($A$33&"#"&1,$I$5:$I$44,0)),"") | I34: =IF(Invoices!J34="","",Invoices!J34&"#"&COUNTIFS(Invoices!$J$5:$J34,Invoices!J34)) | J34: =Invoices!A34 -> 0 | K34: =Invoices!E34 -> 0 | L34: =Invoices!C34 -> 0
A35: =IFERROR(INDEX($J$5:$J$44,MATCH($A$33&"#"&2,$I$5:$I$44,0)),"") | B35: =IFERROR(INDEX($K$5:$K$44,MATCH($A$33&"#"&2,$I$5:$I$44,0)),"") | F35: =IFERROR(INDEX($L$5:$L$44,MATCH($A$33&"#"&2,$I$5:$I$44,0)),"") | I35: =IF(Invoices!J35="","",Invoices!J35&"#"&COUNTIFS(Invoices!$J$5:$J35,Invoices!J35)) | J35: =Invoices!A35 -> 0 | K35: =Invoices!E35 -> 0 | L35: =Invoices!C35 -> 0
A36: =IFERROR(INDEX($J$5:$J$44,MATCH($A$33&"#"&3,$I$5:$I$44,0)),"") | B36: =IFERROR(INDEX($K$5:$K$44,MATCH($A$33&"#"&3,$I$5:$I$44,0)),"") | F36: =IFERROR(INDEX($L$5:$L$44,MATCH($A$33&"#"&3,$I$5:$I$44,0)),"") | I36: =IF(Invoices!J36="","",Invoices!J36&"#"&COUNTIFS(Invoices!$J$5:$J36,Invoices!J36)) | J36: =Invoices!A36 -> 0 | K36: =Invoices!E36 -> 0 | L36: =Invoices!C36 -> 0
A37: =IFERROR(INDEX($J$5:$J$44,MATCH($A$33&"#"&4,$I$5:$I$44,0)),"") | B37: =IFERROR(INDEX($K$5:$K$44,MATCH($A$33&"#"&4,$I$5:$I$44,0)),"") | F37: =IFERROR(INDEX($L$5:$L$44,MATCH($A$33&"#"&4,$I$5:$I$44,0)),"") | I37: =IF(Invoices!J37="","",Invoices!J37&"#"&COUNTIFS(Invoices!$J$5:$J37,Invoices!J37)) | J37: =Invoices!A37 -> 0 | K37: =Invoices!E37 -> 0 | L37: =Invoices!C37 -> 0
A38: =IFERROR(INDEX($J$5:$J$44,MATCH($A$33&"#"&5,$I$5:$I$44,0)),"") | B38: =IFERROR(INDEX($K$5:$K$44,MATCH($A$33&"#"&5,$I$5:$I$44,0)),"") | F38: =IFERROR(INDEX($L$5:$L$44,MATCH($A$33&"#"&5,$I$5:$I$44,0)),"") | I38: =IF(Invoices!J38="","",Invoices!J38&"#"&COUNTIFS(Invoices!$J$5:$J38,Invoices!J38)) | J38: =Invoices!A38 -> 0 | K38: =Invoices!E38 -> 0 | L38: =Invoices!C38 -> 0
A39: =IFERROR(INDEX($J$5:$J$44,MATCH($A$33&"#"&6,$I$5:$I$44,0)),"") | B39: =IFERROR(INDEX($K$5:$K$44,MATCH($A$33&"#"&6,$I$5:$I$44,0)),"") | F39: =IFERROR(INDEX($L$5:$L$44,MATCH($A$33&"#"&6,$I$5:$I$44,0)),"") | I39: =IF(Invoices!J39="","",Invoices!J39&"#"&COUNTIFS(Invoices!$J$5:$J39,Invoices!J39)) | J39: =Invoices!A39 -> 0 | K39: =Invoices!E39 -> 0 | L39: =Invoices!C39 -> 0
F40: =IF($A$40="","",SUMIF(Invoices!$J$5:$J$44,$A$40,Invoices!$C$5:$C$44)) | G40: =IF($A$40="","",D40-F40) | I40: =IF(Invoices!J40="","",Invoices!J40&"#"&COUNTIFS(Invoices!$J$5:$J40,Invoices!J40)) | J40: =Invoices!A40 -> 0 | K40: =Invoices!E40 -> 0 | L40: =Invoices!C40 -> 0
...

Sheet Archived projects
A1: Archived projects | G1: Total billed (finalized): | H1: =SUM(E5:E200) -> 5000
A2: When a project is finished: copy its row from the Projects tab here (paste as VALUES), then clear that row on the Projects tab to free the slot. Invoices keep their project tag, so their history and the invoice/quarter totals are unaffected. Do not re-use an archived project name for a new project.
A4: Project | B4: Client | C4: Total value | D4: Original value | E4: Billed (final) | F4: Unbilled (final) | G4: Date finalized | H4: Notes
A5: Example: Old Website Project | B5: Acme Corp | C5: 5000 | D5: $6,000 | E5: 5000 | F5: 0 | G5: 46022 | H5: Completed — invoices stay tagged on the Invoices tab

Sheet Invoices
A1: Invoices | M1: =YEAR(TODAY())*4+ROUNDUP(MONTH(TODAY())/3,0)-1 -> 8106
A2: Blue cells are yours to fill. Value/Days to Due/PDF Link calculate automatically. Paste a file path in PDF Path (e.g. C:\Invoices\INV-001.pdf) and PDF Link becomes clickable.
A4: Invoice # | B4: Client | C4: Value | D4: PDF Link | E4: Issue Date | F4: Status | G4: Due Date | H4: Days to Due | I4: Payment Date | J4: Project | K4: Original value | L4: Period
A5: 012026 | B5: Acme Corp | C5: 1000 | E5: 46037 | F5: Pending payment | H5: =IF(F5="Pending payment",IF(G5="","",G5-TODAY()),"") | J5: Sample Project | L5: =IF(E5="","",IF($M$1-N5=0,"This quarter",IF($M$1-N5=1,"Last quarter",IF($M$1-N5<0,"Future","Older")))) -> Older | N5: =IF(E5="","",YEAR(E5)*4+ROUNDUP(MONTH(E5)/3,0)-1) -> 8104
H6: =IF(F6="Pending payment",IF(G6="","",G6-TODAY()),"") | L6: =IF(E6="","",IF($M$1-N6=0,"This quarter",IF($M$1-N6=1,"Last quarter",IF($M$1-N6<0,"Future","Older")))) | N6: =IF(E6="","",YEAR(E6)*4+ROUNDUP(MONTH(E6)/3,0)-1)
H7: =IF(F7="Pending payment",IF(G7="","",G7-TODAY()),"") | L7: =IF(E7="","",IF($M$1-N7=0,"This quarter",IF($M$1-N7=1,"Last quarter",IF($M$1-N7<0,"Future","Older")))) | N7: =IF(E7="","",YEAR(E7)*4+ROUNDUP(MONTH(E7)/3,0)-1)
H8: =IF(F8="Pending payment",IF(G8="","",G8-TODAY()),"") | L8: =IF(E8="","",IF($M$1-N8=0,"This quarter",IF($M$1-N8=1,"Last quarter",IF($M$1-N8<0,"Future","Older")))) | N8: =IF(E8="","",YEAR(E8)*4+ROUNDUP(MONTH(E8)/3,0)-1)
H9: =IF(F9="Pending payment",IF(G9="","",G9-TODAY()),"") | L9: =IF(E9="","",IF($M$1-N9=0,"This quarter",IF($M$1-N9=1,"Last quarter",IF($M$1-N9<0,"Future","Older")))) | N9: =IF(E9="","",YEAR(E9)*4+ROUNDUP(MONTH(E9)/3,0)-1)
H10: =IF(F10="Pending payment",IF(G10="","",G10-TODAY()),"") | L10: =IF(E10="","",IF($M$1-N10=0,"This quarter",IF($M$1-N10=1,"Last quarter",IF($M$1-N10<0,"Future","Older")))) | N10: =IF(E10="","",YEAR(E10)*4+ROUNDUP(MONTH(E10)/3,0)-1)
H11: =IF(F11="Pending payment",IF(G11="","",G11-TODAY()),"") | L11: =IF(E11="","",IF($M$1-N11=0,"This quarter",IF($M$1-N11=1,"Last quarter",IF($M$1-N11<0,"Future","Older")))) | N11: =IF(E11="","",YEAR(E11)*4+ROUNDUP(MONTH(E11)/3,0)-1)
H12: =IF(F12="Pending payment",IF(G12="","",G12-TODAY()),"") | L12: =IF(E12="","",IF($M$1-N12=0,"This quarter",IF($M$1-N12=1,"Last quarter",IF($M$1-N12<0,"Future","Older")))) | N12: =IF(E12="","",YEAR(E12)*4+ROUNDUP(MONTH(E12)/3,0)-1)
H13: =IF(F13="Pending payment",IF(G13="","",G13-TODAY()),"") | L13: =IF(E13="","",IF($M$1-N13=0,"This quarter",IF($M$1-N13=1,"Last quarter",IF($M$1-N13<0,"Future","Older")))) | N13: =IF(E13="","",YEAR(E13)*4+ROUNDUP(MONTH(E13)/3,0)-1)
H14: =IF(F14="Pending payment",IF(G14="","",G14-TODAY()),"") | L14: =IF(E14="","",IF($M$1-N14=0,"This quarter",IF($M$1-N14=1,"Last quarter",IF($M$1-N14<0,"Future","Older")))) | N14: =IF(E14="","",YEAR(E14)*4+ROUNDUP(MONTH(E14)/3,0)-1)
H15: =IF(F15="Pending payment",IF(G15="","",G15-TODAY()),"") | L15: =IF(E15="","",IF($M$1-N15=0,"This quarter",IF($M$1-N15=1,"Last quarter",IF($M$1-N15<0,"Future","Older")))) | N15: =IF(E15="","",YEAR(E15)*4+ROUNDUP(MONTH(E15)/3,0)-1)
H16: =IF(F16="Pending payment",IF(G16="","",G16-TODAY()),"") | L16: =IF(E16="","",IF($M$1-N16=0,"This quarter",IF($M$1-N16=1,"Last quarter",IF($M$1-N16<0,"Future","Older")))) | N16: =IF(E16="","",YEAR(E16)*4+ROUNDUP(MONTH(E16)/3,0)-1)
H17: =IF(F17="Pending payment",IF(G17="","",G17-TODAY()),"") | L17: =IF(E17="","",IF($M$1-N17=0,"This quarter",IF($M$1-N17=1,"Last quarter",IF($M$1-N17<0,"Future","Older")))) | N17: =IF(E17="","",YEAR(E17)*4+ROUNDUP(MONTH(E17)/3,0)-1)
... H44: =IF(F44="Pending payment",IF(G44="","",G44-TODAY()),"") | L44: =IF(E44="","",IF($M$1-N44=0,"This quarter",IF($M$1-N44=1,"Last quarter",IF($M$1-N44<0,"Future","Older")))) | N44: =IF(E44="","",YEAR(E44)*4+ROUNDUP(MONTH(E44)/3,0)-1)
B45: TOTAL | C45: =SUM(C5:C44) -> 1000

Sheet Summary (read only)
B2: Ledger Summary
B3: Auto-calculated from the Projects and Invoices tabs.
B5: Projects
B6: Total project value | C6: =SUM(Projects!D5,Projects!D12,Projects!D19,Projects!D26,Projects!D33,Projects!D40,Projects!D47,Projects!D54,Projects!D61,Projects!D68) -> 10000
B7: Invoiced to date | C7: =SUM(Projects!F5,Projects!F12,Projects!F19,Projects!F26,Projects!F33,Projects!F40,Projects!F47,Projects!F54,Projects!F61,Projects!F68) -> 1000
B8: Remaining value | C8: =SUM(Projects!G5,Projects!G12,Projects!G19,Projects!G26,Projects!G33,Projects!G40,Projects!G47,Projects!G54,Projects!G61,Projects!G68) -> 9000
B10: Invoices
B11: Total invoiced (all) | C11: =SUM(Invoices!C5:C44) -> 1000
B12: Outstanding (unpaid) | C12: =SUMIFS(Invoices!C5:C44,Invoices!F5:F44,"Pending payment") -> 1000
B13: Paid | C13: =SUMIFS(Invoices!C5:C44,Invoices!F5:F44,"Paid") -> 0
B14: Overdue (unpaid & past due) | C14: =SUMIFS(Invoices!C5:C44,Invoices!F5:F44,"Pending payment",Invoices!G5:G44,"<"&TODAY()) -> 0
B16: Issued by period (by issue date) | C16: Amount | D16: # inv | F16: =TODAY() -> 46247
B17: This quarter | C17: =SUMIFS(Invoices!$C$5:$C$44,Invoices!$E$5:$E$44,">="&F18,Invoices!$E$5:$E$44,"<"&F19) -> 0 | D17: =COUNTIFS(Invoices!$E$5:$E$44,">="&F18,Invoices!$E$5:$E$44,"<"&F19) -> 0 | F17: =ROUNDUP(MONTH(F16)/3,0) -> 3
B18: Last quarter | C18: =SUMIFS(Invoices!$C$5:$C$44,Invoices!$E$5:$E$44,">="&F20,Invoices!$E$5:$E$44,"<"&F18) -> 0 | D18: =COUNTIFS(Invoices!$E$5:$E$44,">="&F20,Invoices!$E$5:$E$44,"<"&F18) -> 0 | F18: =DATE(YEAR(F16),(F17-1)*3+1,1) -> 46204
B19: This year | C19: =SUMIFS(Invoices!$C$5:$C$44,Invoices!$E$5:$E$44,">="&F21,Invoices!$E$5:$E$44,"<"&F22) -> 1000 | D19: =COUNTIFS(Invoices!$E$5:$E$44,">="&F21,Invoices!$E$5:$E$44,"<"&F22) -> 1 | F19: =EDATE(F18,3) -> 46296
B20: Last year | C20: =SUMIFS(Invoices!$C$5:$C$44,Invoices!$E$5:$E$44,">="&F23,Invoices!$E$5:$E$44,"<"&F21) -> 0 | D20: =COUNTIFS(Invoices!$E$5:$E$44,">="&F23,Invoices!$E$5:$E$44,"<"&F21) -> 0 | F20: =EDATE(F18,-3) -> 46113
B21: Auto-updates with today's date. | F21: =DATE(YEAR(F16),1,1) -> 46023
F22: =DATE(YEAR(F16)+1,1,1) -> 46388
F23: =DATE(YEAR(F16)-1,1,1) -> 45658
